ä¸­
Traceback (most recent call last):
  File "D:/python_learning/test/½Ó¿Ú²âÊÔ/test35.py", line 25, in <module>
    raise Exception(u'ä¸­')
Exception: ä¸­
ä¸­
